<?xml version="1.0" encoding="UTF-8"?>
<testsuite name="homepage_tests.TestConvertEpochToDatetime-20240310225244" tests="2" file="homepage_tests.py" time="0.009" timestamp="2024-03-10T22:52:44" failures="1" errors="0" skipped="0">
	<testcase classname="homepage_tests.TestConvertEpochToDatetime" name="test_convert_epoch_to_datetime_valid" time="0.005" timestamp="2024-03-10T22:52:44"/>
	<testcase classname="homepage_tests.TestConvertEpochToDatetime" name="test_convert_epoch_to_datetime_negative" time="0.004" timestamp="2024-03-10T22:52:44">
		<failure type="AssertionError" message="'Error: Epoch time cannot be negative.' not found in ('&lt;h1&gt;Error: Epoch time cannot be negative.&lt;/h1&gt;', 400)"><![CDATA[Traceback (most recent call last):
  File "C:\Python39\lib\unittest\case.py", line 59, in testPartExecutor
    yield
  File "C:\Python39\lib\unittest\case.py", line 593, in run
    self._callTestMethod(testMethod)
  File "C:\Python39\lib\unittest\case.py", line 550, in _callTestMethod
    method()
  File "d:\bits\devops\random\flask_app\src\unittest\python\homepage_tests.py", line 18, in test_convert_epoch_to_datetime_negative
    self.assertIn('Error: Epoch time cannot be negative.', html_result)
  File "C:\Python39\lib\unittest\case.py", line 1098, in assertIn
    self.fail(self._formatMessage(msg, standardMsg))
  File "C:\Python39\lib\unittest\case.py", line 670, in fail
    raise self.failureException(msg)
AssertionError: 'Error: Epoch time cannot be negative.' not found in ('<h1>Error: Epoch time cannot be negative.</h1>', 400)
]]></failure>
	</testcase>
</testsuite>
